<?xml version="1.0" encoding="utf-8"?>
<robot
  name="trakr">
  <link
    name="base_link">
    <inertial>
      <origin
        xyz="0.0 0.005 0.06"
        rpy="0 0 0" />
      <mass
        value="8.61978" />
      <inertia
        ixx="0.12205"
        ixy="0"
        ixz="0"
        iyy="0.02805"
        iyz="0"
        izz="0.1486" />
    </inertial>
    <visual>
      <origin
        xyz="0 0 0"
        rpy="0 0 0" />
      <geometry>
        <mesh
          filename="../meshes/base_link.STL" />
      </geometry>
      <material
        name="">
        <color
          rgba="0.75294 0.75294 0.75294 1" />
      </material>
    </visual>
    <collision>
      <origin
        xyz="0 0 0"
        rpy="0 0 0" />
      <geometry>
        <mesh
          filename="../meshes/base_link.STL" />
      </geometry>
    </collision>
  </link>
  <link
    name="LF_hip">
    <inertial>
      <origin
        xyz="-0.00431 0 0.05172"
        rpy="0 0 0" />
      <mass
        value="0.77708" />
      <inertia
        ixx="0.00154995934"
        ixy="0"
        ixz="0"
        iyy="0.0010248327"
        iyz="0"
        izz="0.0010248327" />
    </inertial>
    <visual>
      <origin
        xyz="0 0 0"
        rpy="0 0 0" />
      <geometry>
        <mesh
          filename="../meshes/LF_hip.STL" />
      </geometry>
      <material
        name="">
        <color
          rgba="0.50196 0.50196 1 1" />
      </material>
    </visual>
    <collision>
      <origin
        xyz="0 0 0"
        rpy="0 0 0" />
      <geometry>
        <mesh
          filename="../meshes/LF_hip.STL" />
      </geometry>
    </collision>
  </link>
  <joint
    name="LF_adduction"
    type="revolute">
    <origin
      xyz="-0.055 0.174 0.057"
      rpy="1.57079632 0 3.14159265" />
    <parent
      link="base_link" />
    <child
      link="LF_hip" />
    <axis
      xyz="0 0 -1" />
    <limit
      effort="30"
      velocity="10"
      lower="-0.785"
      upper="0.785" />
  </joint>
  <link
    name="LF_thigh">
    <inertial>
      <origin
        xyz="0.042 0.008 -0.019"
        rpy="0 0 0" />
      <mass
        value="1.399" />
      <inertia
        ixx="0.0009092"
        ixy="0"
        ixz="0"
        iyy="0.005343"
        iyz="0"
        izz="0.005343" />
    </inertial>
    <visual>
      <origin
        xyz="0 0 0"
        rpy="0 0 0" />
      <geometry>
        <mesh
          filename="../meshes/LF_thigh.STL" />
      </geometry>
      <material
        name="">
        <color
          rgba="0.75294 0.75294 0.75294 1" />
      </material>
    </visual>
    <collision>
      <origin
        xyz="0 0 0"
        rpy="0 0 0" />
      <geometry>
        <mesh
          filename="../meshes/LF_thigh.STL" />
      </geometry>
    </collision>
  </link>
  <joint
    name="LF_hip"
    type="revolute">
    <origin
      xyz="0.09 0 0.0565"
      rpy="-1.57079632 0.80983 -1.57079632" />
    <parent
      link="LF_hip" />
    <child
      link="LF_thigh" />
    <axis
      xyz="0 0 -1" />
    <limit
      effort="30"
      velocity="10"
      lower="-0.872"
      upper="1.300" />
  </joint>
  <link
    name="LF_shank">
    <inertial>
      <origin
        xyz="0.106 -0.009 0"
        rpy="0 0 0" />
      <mass
        value="0.187" />
      <inertia
        ixx="0.0009106833"
        ixy="0.0"
        ixz="0.0"
        iyy="0.00131001449"
        iyz="0.0"
        izz="0.00131001449" />
    </inertial>
    <visual>
      <origin
        xyz="0 0 0"
        rpy="0 0 0" />
      <geometry>
        <mesh
          filename="../meshes/LF_shank.STL" />
      </geometry>
      <material
        name="">
        <color
          rgba="0.75294 0.75294 0.75294 1" />
      </material>
    </visual>
    <collision>
      <origin
        xyz="0 0 0"
        rpy="0 0 0" />
      <geometry>
        <mesh
          filename="../meshes/LF_shank.STL" />
      </geometry>
    </collision>
  </link>
  <joint
    name="LF_knee"
    type="revolute">
    <origin
      xyz="0.20077 0 0"
      rpy="0 0 -1.57079632" />
    <parent
      link="LF_thigh" />
    <child
      link="LF_shank" />
    <axis
      xyz="0 0 -1" />
    <limit
      effort="30"
      velocity="10"
      lower="-0.450"
      upper="0.900" />
  </joint>
  <link
    name="LF_toe">
    <inertial>
      <origin
        xyz="0 0.0070197 0.012316"
        rpy="0 0 0" />
      <mass
        value="0.040" />
      <inertia
        ixx="0.000008450"
        ixy="0"
        ixz="0"
        iyy="0.000008000"
        iyz="0"
        izz="0.000010113" />
    </inertial>
    <visual>
      <origin
        xyz="0 0 0"
        rpy="0 0 0" />
      <geometry>
        <mesh
          filename="../meshes/LF_toe.STL" />
      </geometry>
      <material
        name="">
        <color
          rgba="0.29804 0.29804 0.29804 1" />
      </material>
    </visual>
    <collision>
      <origin
        xyz="0 0 0"
        rpy="0 0 0" />
      <geometry>
        <mesh
          filename="../meshes/LF_toe.STL" />
      </geometry>
    </collision>
  </link>
  <joint
    name="LF_toe"
    type="fixed"
    dont_collapse="true">
    <origin
      xyz="0.20917 0 0"
      rpy="3.14159265 1.57079632 0" />
    <parent
      link="LF_shank" />
    <child
      link="LF_toe" />
    <axis
      xyz="0 0 0" />
  </joint>
  <link
    name="RF_hip">
    <inertial>
      <origin
        xyz="0.00431 0 -0.05172"
        rpy="0 0 0" />
      <mass
        value="0.77708" />
      <inertia
        ixx="0.00154995934"
        ixy="0"
        ixz="0"
        iyy="0.0010248327"
        iyz="0"
        izz="0.0010248327" />
    </inertial>
    <visual>
      <origin
        xyz="0 0 0"
        rpy="0 0 0" />
      <geometry>
        <mesh
          filename="../meshes/RF_hip.STL" />
      </geometry>
      <material
        name="">
        <color
          rgba="0.50196 0.50196 1 1" />
      </material>
    </visual>
    <collision>
      <origin
        xyz="0 0 0"
        rpy="0 0 0" />
      <geometry>
        <mesh
          filename="../meshes/RF_hip.STL" />
      </geometry>
    </collision>
  </link>
  <joint
    name="RF_adduction"
    type="revolute">
    <origin
      xyz="0.055 0.174 0.057"
      rpy="-1.57079632 0 3.14159265" />
    <parent
      link="base_link" />
    <child
      link="RF_hip" />
    <axis
      xyz="0 0 1" />
    <limit
      effort="30"
      velocity="10"
      lower="-0.785"
      upper="0.785" />
  </joint>
  <link
    name="RF_thigh">
    <inertial>
      <origin
        xyz="0.042 0.008 0.019"
        rpy="0 0 0" />
      <mass
        value="1.399" />
      <inertia
        ixx="0.0009092"
        ixy="0"
        ixz="0"
        iyy="0.005343"
        iyz="0"
        izz="0.005343" />
    </inertial>
    <visual>
      <origin
        xyz="0 0 0"
        rpy="0 0 0" />
      <geometry>
        <mesh
          filename="../meshes/RF_thigh.STL" />
      </geometry>
      <material
        name="">
        <color
          rgba="0.75294 0.75294 0.75294 1" />
      </material>
    </visual>
    <collision>
      <origin
        xyz="0 0 0"
        rpy="0 0 0" />
      <geometry>
        <mesh
          filename="../meshes/RF_thigh.STL" />
      </geometry>
    </collision>
  </link>
  <joint
    name="RF_hip"
    type="revolute">
    <origin
      xyz="-0.09 0 -0.0565"
      rpy="1.57079632 -0.80983 1.57079632" />
    <parent
      link="RF_hip" />
    <child
      link="RF_thigh" />
    <axis
      xyz="0 0 -1" />
    <limit
      effort="30"
      velocity="10"
      lower="-0.872"
      upper="1.300" />
    </joint>
  <link
    name="RF_shank">
    <inertial>
      <origin
        xyz="0.106 -0.009 0"
        rpy="0 0 0" />
      <mass
        value="0.187" />
      <inertia
        ixx="0.0009106833"
        ixy="0.0"
        ixz="0.0"
        iyy="0.00131001449"
        iyz="0.0"
        izz="0.00131001449" />
    </inertial>
    <visual>
      <origin
        xyz="0 0 0"
        rpy="0 0 0" />
      <geometry>
        <mesh
          filename="../meshes/RF_shank.STL" />
      </geometry>
      <material
        name="">
        <color
          rgba="0.75294 0.75294 0.75294 1" />
      </material>
    </visual>
    <collision>
      <origin
        xyz="0 0 0"
        rpy="0 0 0" />
      <geometry>
        <mesh
          filename="../meshes/RF_shank.STL" />
      </geometry>
    </collision>
  </link>
  <joint
    name="RF_knee"
    type="revolute">
    <origin
      xyz="0.20077 0 0"
      rpy="0 0 -1.57079632" />
    <parent
      link="RF_thigh" />
    <child
      link="RF_shank" />
    <axis
      xyz="0 0 -1" />
    <limit
      effort="30"
      velocity="10"
      lower="-0.450"
      upper="0.900" />
  </joint>
  <link
    name="RF_toe">
    <inertial>
      <origin
        xyz="0 0.0070197 0.012316"
        rpy="0 0 0" />
      <mass
        value="0.040" />
      <inertia
        ixx="0.000008450"
        ixy="0"
        ixz="0"
        iyy="0.000008000"
        iyz="0"
        izz="0.000010113" />
    </inertial>
    <visual>
      <origin
        xyz="0 0 0"
        rpy="0 0 0" />
      <geometry>
        <mesh
          filename="../meshes/RF_toe.STL" />
      </geometry>
      <material
        name="">
        <color
          rgba="0.29804 0.29804 0.29804 1" />
      </material>
    </visual>
    <collision>
      <origin
        xyz="0 0 0"
        rpy="0 0 0" />
      <geometry>
        <mesh
          filename="../meshes/RF_toe.STL" />
      </geometry>
    </collision>
  </link>
  <joint
    name="RF_toe"
    type="fixed"
    dont_collapse="true">
    <origin
      xyz="0.20917 0 0"
      rpy="3.14159265 1.57079632 0" />
    <parent
      link="RF_shank" />
    <child
      link="RF_toe" />
    <axis
      xyz="0 0 0" />
  </joint>
  <link
    name="LB_hip">
    <inertial>
      <origin
        xyz="-0.00431 0 -0.05172"
        rpy="0 0 0" />
      <mass
        value="0.77708" />
      <inertia
        ixx="0.00154995934"
        ixy="0"
        ixz="0"
        iyy="0.0010248327"
        iyz="0"
        izz="0.0010248327" />
    </inertial>
    <visual>
      <origin
        xyz="0 0 0"
        rpy="0 0 0" />
      <geometry>
        <mesh
          filename="../meshes/LB_hip.STL" />
      </geometry>
      <material
        name="">
        <color
          rgba="0.50196 0.50196 1 1" />
      </material>
    </visual>
    <collision>
      <origin
        xyz="0 0 0"
        rpy="0 0 0" />
      <geometry>
        <mesh
          filename="../meshes/LB_hip.STL" />
      </geometry>
    </collision>
  </link>
  <joint
    name="LB_adduction"
    type="revolute">
    <origin
      xyz="-0.055 -0.174 0.057"
      rpy="1.57079632 0 3.14159265" />
    <parent
      link="base_link" />
    <child
      link="LB_hip" />
    <axis
      xyz="0 0 -1" />
    <limit
      effort="30"
      velocity="10"
      lower="-0.785"
      upper="0.785" />
  </joint>
  <link
    name="LB_thigh">
    <inertial>
      <origin
        xyz="0.042 0.008 -0.019"
        rpy="0 0 0" />
      <mass
        value="1.399" />
      <inertia
        ixx="0.0009092"
        ixy="0"
        ixz="0"
        iyy="0.005343"
        iyz="0"
        izz="0.005343" />
    </inertial>
    <visual>
      <origin
        xyz="0 0 0"
        rpy="0 0 0" />
      <geometry>
        <mesh
          filename="../meshes/LB_thigh.STL" />
      </geometry>
      <material
        name="">
        <color
          rgba="0.75294 0.75294 0.75294 1" />
      </material>
    </visual>
    <collision>
      <origin
        xyz="0 0 0"
        rpy="0 0 0" />
      <geometry>
        <mesh
          filename="../meshes/LB_thigh.STL" />
      </geometry>
    </collision>
  </link>
  <joint
    name="LB_hip"
    type="revolute">
    <origin
      xyz="0.09 0 -0.0565"
      rpy="-1.57079632 0.80983 -1.57079632" />
    <parent
      link="LB_hip" />
    <child
      link="LB_thigh" />
    <axis
      xyz="0 0 -1" />
    <limit
      effort="30"
      velocity="10"
      lower="-0.872"
      upper="1.300" />
  </joint>
  <link
    name="LB_shank">
    <inertial>
      <origin
        xyz="0.106 -0.009 0"
        rpy="0 0 0" />
      <mass
        value="0.187" />
      <inertia
        ixx="0.0009106833"
        ixy="0.0"
        ixz="0.0"
        iyy="0.00131001449"
        iyz="0.0"
        izz="0.00131001449" />
    </inertial>
    <visual>
      <origin
        xyz="0 0 0"
        rpy="0 0 0" />
      <geometry>
        <mesh
          filename="../meshes/LB_shank.STL" />
      </geometry>
      <material
        name="">
        <color
          rgba="0.75294 0.75294 0.75294 1" />
      </material>
    </visual>
    <collision>
      <origin
        xyz="0 0 0"
        rpy="0 0 0" />
      <geometry>
        <mesh
          filename="../meshes/LB_shank.STL" />
      </geometry>
    </collision>
  </link>
  <joint
    name="LB_knee"
    type="revolute">
    <origin
      xyz="0.20077 0 0"
      rpy="0 0 -1.57079632" />
    <parent
      link="LB_thigh" />
    <child
      link="LB_shank" />
    <axis
      xyz="0 0 -1" />
    <limit
      effort="30"
      velocity="10"
      lower="-0.450"
      upper="0.900" />
  </joint>
  <link
    name="LB_toe">
    <inertial>
      <origin
        xyz="0 0.0070197 0.012316"
        rpy="0 0 0" />
      <mass
        value="0.040" />
      <inertia
        ixx="0.000008450"
        ixy="0"
        ixz="0"
        iyy="0.000008000"
        iyz="0"
        izz="0.000010113" />
    </inertial>
    <visual>
      <origin
        xyz="0 0 0"
        rpy="0 0 0" />
      <geometry>
        <mesh
          filename="../meshes/LB_toe.STL" />
      </geometry>
      <material
        name="">
        <color
          rgba="0.29804 0.29804 0.29804 1" />
      </material>
    </visual>
    <collision>
      <origin
        xyz="0 0 0"
        rpy="0 0 0" />
      <geometry>
        <mesh
          filename="../meshes/LB_toe.STL" />
      </geometry>
    </collision>
  </link>
  <joint
    name="LB_toe"
    type="fixed"
    dont_collapse="true">
    <origin
      xyz="0.20917 0 0"
      rpy="3.14159265 1.57079632 0" />
    <parent
      link="LB_shank" />
    <child
      link="LB_toe" />
    <axis
      xyz="0 0 0" />
  </joint>
  <link
    name="RB_hip">
    <inertial>
      <origin
        xyz="0.00431 0 0.05172"
        rpy="0 0 0" />
      <mass
        value="0.77708" />
      <inertia
        ixx="0.00154995934"
        ixy="0"
        ixz="0"
        iyy="0.0010248327"
        iyz="0"
        izz="0.0010248327" />
    </inertial>
    <visual>
      <origin
        xyz="0 0 0"
        rpy="0 0 0" />
      <geometry>
        <mesh
          filename="../meshes/RB_hip.STL" />
      </geometry>
      <material
        name="">
        <color
          rgba="0.50196 0.50196 1 1" />
      </material>
    </visual>
    <collision>
      <origin
        xyz="0 0 0"
        rpy="0 0 0" />
      <geometry>
        <mesh
          filename="../meshes/RB_hip.STL" />
      </geometry>
    </collision>
  </link>
  <joint
    name="RB_adduction"
    type="revolute">
    <origin
      xyz="0.055 -0.174 0.057"
      rpy="-1.57079632 0 3.14159265" />
    <parent
      link="base_link" />
    <child
      link="RB_hip" />
    <axis
      xyz="0 0 1" />
    <limit
      effort="30"
      velocity="10"
      lower="-0.785"
      upper="0.785" />
  </joint>
  <link
    name="RB_thigh">
    <inertial>
      <origin
        xyz="0.042 0.008 0.019"
        rpy="0 0 0" />
      <mass
        value="1.399" />
      <inertia
        ixx="0.0009092"
        ixy="0"
        ixz="0"
        iyy="0.005343"
        iyz="0"
        izz="0.005343" />
    </inertial>
    <visual>
      <origin
        xyz="0 0 0"
        rpy="0 0 0" />
      <geometry>
        <mesh
          filename="../meshes/RB_thigh.STL" />
      </geometry>
      <material
        name="">
        <color
          rgba="0.75294 0.75294 0.75294 1" />
      </material>
    </visual>
    <collision>
      <origin
        xyz="0 0 0"
        rpy="0 0 0" />
      <geometry>
        <mesh
          filename="../meshes/RB_thigh.STL" />
      </geometry>
    </collision>
  </link>
  <joint
    name="RB_hip"
    type="revolute">
    <origin
      xyz="-0.09 0 0.0565"
      rpy="1.57079632 -0.80983 1.57079632" />
    <parent
      link="RB_hip" />
    <child
      link="RB_thigh" />
    <axis
      xyz="0 0 -1" />
    <limit
      effort="30"
      velocity="10"
      lower="-0.872"
      upper="1.300" />  
  </joint>
  <link
    name="RB_shank">
    <inertial>
      <origin
        xyz="0.106 -0.009 0"
        rpy="0 0 0" />
      <mass
        value="0.187" />
      <inertia
        ixx="0.0009106833"
        ixy="0.0"
        ixz="0.0"
        iyy="0.00131001449"
        iyz="0.0"
        izz="0.00131001449" />
    </inertial>
    <visual>
      <origin
        xyz="0 0 0"
        rpy="0 0 0" />
      <geometry>
        <mesh
          filename="../meshes/RB_shank.STL" />
      </geometry>
      <material
        name="">
        <color
          rgba="0.75294 0.75294 0.75294 1" />
      </material>
    </visual>
    <collision>
      <origin
        xyz="0 0 0"
        rpy="0 0 0" />
      <geometry>
        <mesh
          filename="../meshes/RB_shank.STL" />
      </geometry>
    </collision>
  </link>
  <joint
    name="RB_knee"
    type="revolute">
    <origin
      xyz="0.20077 0 0"
      rpy="0 0 -1.57079632" />
    <parent
      link="RB_thigh" />
    <child
      link="RB_shank" />
    <axis
      xyz="0 0 -1" />
    <limit
      effort="30"
      velocity="10"
      lower="-0.450"
      upper="0.900" />
  </joint>
  <link
    name="RB_toe">
    <inertial>
      <origin
        xyz="0 0.0070197 0.012316"
        rpy="0 0 0" />
      <mass
        value="0.040" />
      <inertia
        ixx="0.000008450"
        ixy="0"
        ixz="0"
        iyy="0.000008000"
        iyz="0"
        izz="0.000010113" />
    </inertial>
    <visual>
      <origin
        xyz="0 0 0"
        rpy="0 0 0" />
      <geometry>
        <mesh
          filename="../meshes/RB_toe.STL" />
      </geometry>
      <material
        name="">
        <color
          rgba="0.29804 0.29804 0.29804 1" />
      </material>
    </visual>
    <collision>
      <origin
        xyz="0 0 0"
        rpy="0 0 0" />
      <geometry>
        <mesh
          filename="../meshes/RB_toe.STL" />
      </geometry>
    </collision>
  </link>
  <joint
    name="RB_toe"
    type="fixed"
    dont_collapse="true">
    <origin
      xyz="0.20917 0 0"
      rpy="3.14159265 1.57079632 0" />
    <parent
      link="RB_shank" />
    <child
      link="RB_toe" />
    <axis
      xyz="0 0 0" />
  </joint>
</robot>